[2025-05-21 08:09:53 -0400] [25008] [DEBUG] Current configuration:
  config: ./gunicorn.conf.py
  wsgi_app: None
  bind: ['0.0.0.0:5000']
  backlog: 2048
  workers: 1
  worker_class: sync
  threads: 1
  worker_connections: 1000
  max_requests: 0
  max_requests_jitter: 0
  timeout: 30
  graceful_timeout: 30
  keepalive: 2
  limit_request_line: 4094
  limit_request_fields: 100
  limit_request_field_size: 8190
  reload: False
  reload_engine: auto
  reload_extra_files: []
  spew: False
  check_config: False
  print_config: False
  preload_app: False
  sendfile: None
  reuse_port: False
  chdir: /home/ubuntu/prototipo_web/recursosweb
  daemon: False
  raw_env: []
  pidfile: None
  worker_tmp_dir: None
  user: 1000
  group: 1000
  umask: 0
  initgroups: False
  tmp_upload_dir: None
  secure_scheme_headers: {'X-FORWARDED-PROTOCOL': 'ssl', 'X-FORWARDED-PROTO': 'https', 'X-FORWARDED-SSL': 'on'}
  forwarded_allow_ips: ['127.0.0.1']
  accesslog: None
  disable_redirect_access_to_syslog: False
  access_log_format: %(h)s %(l)s %(u)s %(t)s "%(r)s" %(s)s %(b)s "%(f)s" "%(a)s"
  errorlog: gunicorn_debug.log
  loglevel: debug
  capture_output: False
  logger_class: gunicorn.glogging.Logger
  logconfig: None
  logconfig_dict: {}
  logconfig_json: None
  syslog_addr: udp://localhost:514
  syslog: False
  syslog_prefix: None
  syslog_facility: user
  enable_stdio_inheritance: False
  statsd_host: None
  dogstatsd_tags: 
  statsd_prefix: 
  proc_name: None
  default_proc_name: wsgi:app
  pythonpath: None
  paste: None
  on_starting: <function OnStarting.on_starting at 0x7f5ecb3d3ec0>
  on_reload: <function OnReload.on_reload at 0x7f5ecb3f0040>
  when_ready: <function WhenReady.when_ready at 0x7f5ecb3f0180>
  pre_fork: <function Prefork.pre_fork at 0x7f5ecb3f02c0>
  post_fork: <function Postfork.post_fork at 0x7f5ecb3f0400>
  post_worker_init: <function PostWorkerInit.post_worker_init at 0x7f5ecb3f0540>
  worker_int: <function WorkerInt.worker_int at 0x7f5ecb3f0680>
  worker_abort: <function WorkerAbort.worker_abort at 0x7f5ecb3f07c0>
  pre_exec: <function PreExec.pre_exec at 0x7f5ecb3f0900>
  pre_request: <function PreRequest.pre_request at 0x7f5ecb3f0a40>
  post_request: <function PostRequest.post_request at 0x7f5ecb3f0ae0>
  child_exit: <function ChildExit.child_exit at 0x7f5ecb3f0c20>
  worker_exit: <function WorkerExit.worker_exit at 0x7f5ecb3f0d60>
  nworkers_changed: <function NumWorkersChanged.nworkers_changed at 0x7f5ecb3f0ea0>
  on_exit: <function OnExit.on_exit at 0x7f5ecb3f0fe0>
  ssl_context: <function NewSSLContext.ssl_context at 0x7f5ecb3f11c0>
  proxy_protocol: False
  proxy_allow_ips: ['127.0.0.1']
  keyfile: None
  certfile: None
  ssl_version: 2
  cert_reqs: 0
  ca_certs: None
  suppress_ragged_eofs: True
  do_handshake_on_connect: False
  ciphers: None
  raw_paste_global_conf: []
  strip_header_spaces: False
[2025-05-21 08:09:53 -0400] [25008] [INFO] Starting gunicorn 21.2.0
[2025-05-21 08:09:53 -0400] [25008] [DEBUG] Arbiter booted
[2025-05-21 08:09:53 -0400] [25008] [INFO] Listening at: http://0.0.0.0:5000 (25008)
[2025-05-21 08:09:53 -0400] [25008] [INFO] Using worker: sync
[2025-05-21 08:09:53 -0400] [25009] [INFO] Booting worker with pid: 25009
[2025-05-21 08:09:53 -0400] [25008] [DEBUG] 1 workers
[2025-05-21 08:09:54 -0400] [25009] [ERROR] Exception in worker process
Traceback (most recent call last):
  File "/usr/local/lib/python3.11/dist-packages/gunicorn/arbiter.py", line 609, in spawn_worker
    worker.init_process()
  File "/usr/local/lib/python3.11/dist-packages/gunicorn/workers/base.py", line 134, in init_process
    self.load_wsgi()
  File "/usr/local/lib/python3.11/dist-packages/gunicorn/workers/base.py", line 146, in load_wsgi
    self.wsgi = self.app.wsgi()
                ^^^^^^^^^^^^^^^
  File "/usr/local/lib/python3.11/dist-packages/gunicorn/app/base.py", line 67, in wsgi
    self.callable = self.load()
                    ^^^^^^^^^^^
  File "/usr/local/lib/python3.11/dist-packages/gunicorn/app/wsgiapp.py", line 58, in load
    return self.load_wsgiapp()
           ^^^^^^^^^^^^^^^^^^^
  File "/usr/local/lib/python3.11/dist-packages/gunicorn/app/wsgiapp.py", line 48, in load_wsgiapp
    return util.import_app(self.app_uri)
           ^^^^^^^^^^^^^^^^^^^^^^^^^^^^^
  File "/usr/local/lib/python3.11/dist-packages/gunicorn/util.py", line 371, in import_app
    mod = importlib.import_module(module)
          ^^^^^^^^^^^^^^^^^^^^^^^^^^^^^^^
  File "/usr/lib/python3.11/importlib/__init__.py", line 126, in import_module
    return _bootstrap._gcd_import(name[level:], package, level)
           ^^^^^^^^^^^^^^^^^^^^^^^^^^^^^^^^^^^^^^^^^^^^^^^^^^^^
  File "<frozen importlib._bootstrap>", line 1206, in _gcd_import
  File "<frozen importlib._bootstrap>", line 1178, in _find_and_load
  File "<frozen importlib._bootstrap>", line 1149, in _find_and_load_unlocked
  File "<frozen importlib._bootstrap>", line 690, in _load_unlocked
  File "<frozen importlib._bootstrap_external>", line 940, in exec_module
  File "<frozen importlib._bootstrap>", line 241, in _call_with_frames_removed
  File "/home/ubuntu/prototipo_web/recursosweb/wsgi.py", line 9, in <module>
    from src.main import app
  File "/home/ubuntu/prototipo_web/recursosweb/src/main.py", line 63, in <module>
    aeropuerto = Aeropuerto(codigo='TFS', nombre='Tenerife Sur', ciudad='Tenerife', pais='Espa√±a')
                 ^^^^^^^^^^^^^^^^^^^^^^^^^^^^^^^^^^^^^^^^^^^^^^^^^^^^^^^^^^^^^^^^^^^^^^^^^^^^^^^^^
  File "<string>", line 4, in __init__
  File "/usr/local/lib/python3.11/dist-packages/sqlalchemy/orm/state.py", line 571, in _initialize_instance
    with util.safe_reraise():
  File "/usr/local/lib/python3.11/dist-packages/sqlalchemy/util/langhelpers.py", line 224, in __exit__
    raise exc_value.with_traceback(exc_tb)
  File "/usr/local/lib/python3.11/dist-packages/sqlalchemy/orm/state.py", line 569, in _initialize_instance
    manager.original_init(*mixed[1:], **kwargs)
  File "/usr/local/lib/python3.11/dist-packages/sqlalchemy/orm/decl_base.py", line 2173, in _declarative_constructor
    raise TypeError(
TypeError: 'ciudad' is an invalid keyword argument for Aeropuerto
[2025-05-21 08:09:54 -0400] [25009] [INFO] Worker exiting (pid: 25009)
[2025-05-21 08:09:54 -0400] [25008] [ERROR] Worker (pid:25009) exited with code 3
[2025-05-21 08:09:54 -0400] [25008] [ERROR] Shutting down: Master
[2025-05-21 08:09:54 -0400] [25008] [ERROR] Reason: Worker failed to boot.
